<?xml version="1.0"?>
<robot name="tube_arm_with_base">

  <link name="base_link">
    <visual>
      <origin xyz="0 0 0.01"/>
      <geometry>
        <box size="0.1 0.1 0.02"/>
      </geometry>
    </visual>
  </link>

  <link name="link1">
    <inertial>
      <origin xyz="0 0 0.05"/>
      <mass value="1"/>
      <inertia ixx="0.01" iyy="0.01" izz="0.01" ixy="0" ixz="0" iyz="0"/>
    </inertial>
    <visual>
      <origin xyz="0 0 0.05"/>
      <geometry>
        <cylinder radius="0.02" length="0.1"/>
      </geometry>
    </visual>
  </link>

  <joint name="joint1" type="revolute">
    <parent link="base_link"/>
    <child link="link1"/>
    <origin xyz="0 0 0.02"/>
    <axis xyz="0 0 1"/>
    <limit lower="-3.14" upper="3.14" effort="10" velocity="1.0"/>
  </joint>

  <link name="link2">
    <inertial>
      <origin xyz="0 0 0.05"/>
      <mass value="1"/>
      <inertia ixx="0.01" iyy="0.01" izz="0.01" ixy="0" ixz="0" iyz="0"/>
    </inertial>
    <visual>
      <origin xyz="0 0 0.05"/>
      <geometry>
        <cylinder radius="0.02" length="0.1"/>
      </geometry>
    </visual>
  </link>

  <joint name="joint2" type="revolute">
    <parent link="link1"/>
    <child link="link2"/>
    <origin xyz="0 0 0.1"/>
    <axis xyz="0 1 0"/>
    <limit lower="-3.14" upper="3.14" effort="10" velocity="1.0"/>
  </joint>

  <link name="link3">
    <inertial>
      <origin xyz="0 0 0.05"/>
      <mass value="1"/>
      <inertia ixx="0.01" iyy="0.01" izz="0.01" ixy="0" ixz="0" iyz="0"/>
    </inertial>
    <visual>
      <origin xyz="0 0 0.05"/>
      <geometry>
        <cylinder radius="0.02" length="0.1"/>
      </geometry>
    </visual>
  </link>

  <joint name="joint3" type="revolute">
    <parent link="link2"/>
    <child link="link3"/>
    <origin xyz="0 0 0.1"/>
    <axis xyz="1 0 0"/>
    <limit lower="-3.14" upper="3.14" effort="10" velocity="1.0"/>
  </joint>

</robot>
